### Шанс вопроса: 3%

`create_task()` — это метод в модуле `asyncio` для Python, который создаёт и планирует выполнение задачи (coroutine) асинхронно. Он является частью стандартной библиотеки и используется для асинхронного программирования с помощью цикла событий (event loop).

### Пример использования:
```python
import asyncio

async def greet(name):
    print(f"Hello, {name}!")
    await asyncio.sleep(1)  # Имитация асинхронной задержки
    print(f"Goodbye, {name}!")

async def main():
    task = asyncio.create_task(greet("World"))
    print("Task created")
    
    await asyncio.sleep(0)  # Позволяем циклу событий немного поработать
    await task  # Ожидаем завершения задачи

# Запуск главного асинхронного цикла
asyncio.run(main())
```

### Основные характеристики:
1. **Планирование задач**: `create_task()` планирует выполнение переданной корутины (coroutine) в цикл событий, что позволяет асинхронно выполнять несколько задач одновременно.
2. **Возвращаемое значение**: Метод возвращает объект `Task`, который можно использовать для управления и отслеживания состояния задачи (например, отмена или ожидание завершения).
3. **Поддержка цикла событий**: Работает только в рамках цикла событий, предоставляемого `asyncio`.

### Пример использования с отменой задачи:
```python
import asyncio

async def greet(name):
    print(f"Hello, {name}!")
    await asyncio.sleep(1)  # Имитация асинхронной задержки
    print(f"Goodbye, {name}!")

async def main():
    task = asyncio.create_task(greet("World"))
    await asyncio.sleep(0.5)  # Небольшая пауза для начала выполнения задачи
    
    print("Canceling the task...")
    task.cancel()  # Отмена задачи
    
    try:
        await task  # Ожидаем завершения отменённой задачи
    except asyncio.CancelledError:
        print("Task was canceled.")

asyncio.run(main())
```

Этот пример демонстрирует, как создать задачу и отменить её до завершения.